{'TIME':2022-01-04 15:25:02,153,'ADDRESS':'None','URL': 'None','TYPE':'ERROR','MODULE':'_base','MSG':{exception calling callback for <Future at 0x19052de7d48 state=finished returned Response>}}
Traceback (most recent call last):
  File "C:\Users\Administrador.WIN-DUOGLHGMSST\AppData\Local\Programs\Python\Python37\lib\concurrent\futures\_base.py", line 324, in _invoke_callbacks
    callback(self)
  File "C:\Users\Administrador.WIN-DUOGLHGMSST\AppData\Local\Programs\Python\Python37\lib\asyncio\futures.py", line 365, in _call_set_state
    dest_loop.call_soon_threadsafe(_set_state, destination, source)
  File "C:\Users\Administrador.WIN-DUOGLHGMSST\AppData\Local\Programs\Python\Python37\lib\asyncio\base_events.py", line 736, in call_soon_threadsafe
    self._check_closed()
  File "C:\Users\Administrador.WIN-DUOGLHGMSST\AppData\Local\Programs\Python\Python37\lib\asyncio\base_events.py", line 479, in _check_closed
    raise RuntimeError('Event loop is closed')
RuntimeError: Event loop is closed
{'TIME':2022-01-04 15:27:31,769,'ADDRESS':'None','URL': 'None','TYPE':'ERROR','MODULE':'_base','MSG':{exception calling callback for <Future at 0x19052e76a08 state=finished returned Response>}}
Traceback (most recent call last):
  File "C:\Users\Administrador.WIN-DUOGLHGMSST\AppData\Local\Programs\Python\Python37\lib\concurrent\futures\_base.py", line 324, in _invoke_callbacks
    callback(self)
  File "C:\Users\Administrador.WIN-DUOGLHGMSST\AppData\Local\Programs\Python\Python37\lib\asyncio\futures.py", line 365, in _call_set_state
    dest_loop.call_soon_threadsafe(_set_state, destination, source)
  File "C:\Users\Administrador.WIN-DUOGLHGMSST\AppData\Local\Programs\Python\Python37\lib\asyncio\base_events.py", line 736, in call_soon_threadsafe
    self._check_closed()
  File "C:\Users\Administrador.WIN-DUOGLHGMSST\AppData\Local\Programs\Python\Python37\lib\asyncio\base_events.py", line 479, in _check_closed
    raise RuntimeError('Event loop is closed')
RuntimeError: Event loop is closed
{'TIME':2022-01-04 15:27:34,119,'ADDRESS':'None','URL': 'None','TYPE':'ERROR','MODULE':'_base','MSG':{exception calling callback for <Future at 0x19052e84708 state=finished returned Response>}}
Traceback (most recent call last):
  File "C:\Users\Administrador.WIN-DUOGLHGMSST\AppData\Local\Programs\Python\Python37\lib\concurrent\futures\_base.py", line 324, in _invoke_callbacks
    callback(self)
  File "C:\Users\Administrador.WIN-DUOGLHGMSST\AppData\Local\Programs\Python\Python37\lib\asyncio\futures.py", line 365, in _call_set_state
    dest_loop.call_soon_threadsafe(_set_state, destination, source)
  File "C:\Users\Administrador.WIN-DUOGLHGMSST\AppData\Local\Programs\Python\Python37\lib\asyncio\base_events.py", line 736, in call_soon_threadsafe
    self._check_closed()
  File "C:\Users\Administrador.WIN-DUOGLHGMSST\AppData\Local\Programs\Python\Python37\lib\asyncio\base_events.py", line 479, in _check_closed
    raise RuntimeError('Event loop is closed')
RuntimeError: Event loop is closed
