{'TIME':2022-01-05 12:19:46,952,'ADDRESS':'127.0.0.1','URL': 'http://localhost:4000/actividad/PDF?CCODACT=00017192&CTIPSER=R&CCODPLA=72539751002&CNRODNI=99999999&CNRORUC=20125327509&CCODUSU=9999','TYPE':'ERROR','MODULE':'channel','MSG':{Exception while serving /actividad/PDF}}
Traceback (most recent call last):
  File "C:\xampp\htdocs\CLANAD_PY\FlaskAPI\app\src\Actividad.py", line 187, in PDF_Actividad
    loActividad.setData(R1_json["DATA"])
NameError: name 'loActividad' is not defined

During handling of the above exception, another exception occurred:

Traceback (most recent call last):
  File "C:\Users\Administrador.WIN-DUOGLHGMSST\AppData\Local\Programs\Python\Python37\lib\site-packages\waitress\channel.py", line 397, in service
    task.service()
  File "C:\Users\Administrador.WIN-DUOGLHGMSST\AppData\Local\Programs\Python\Python37\lib\site-packages\waitress\task.py", line 168, in service
    self.execute()
  File "C:\Users\Administrador.WIN-DUOGLHGMSST\AppData\Local\Programs\Python\Python37\lib\site-packages\waitress\task.py", line 434, in execute
    app_iter = self.channel.server.application(environ, start_response)
  File "C:\Users\Administrador.WIN-DUOGLHGMSST\AppData\Local\Programs\Python\Python37\lib\site-packages\flask\app.py", line 2091, in __call__
    return self.wsgi_app(environ, start_response)
  File "C:\Users\Administrador.WIN-DUOGLHGMSST\AppData\Local\Programs\Python\Python37\lib\site-packages\flask\app.py", line 2076, in wsgi_app
    response = self.handle_exception(e)
  File "C:\Users\Administrador.WIN-DUOGLHGMSST\AppData\Local\Programs\Python\Python37\lib\site-packages\flask\app.py", line 2073, in wsgi_app
    response = self.full_dispatch_request()
  File "C:\Users\Administrador.WIN-DUOGLHGMSST\AppData\Local\Programs\Python\Python37\lib\site-packages\flask\app.py", line 1518, in full_dispatch_request
    rv = self.handle_user_exception(e)
  File "C:\Users\Administrador.WIN-DUOGLHGMSST\AppData\Local\Programs\Python\Python37\lib\site-packages\flask\app.py", line 1516, in full_dispatch_request
    rv = self.dispatch_request()
  File "C:\Users\Administrador.WIN-DUOGLHGMSST\AppData\Local\Programs\Python\Python37\lib\site-packages\flask\app.py", line 1502, in dispatch_request
    return self.ensure_sync(self.view_functions[rule.endpoint])(**req.view_args)
  File "C:\Users\Administrador.WIN-DUOGLHGMSST\AppData\Local\Programs\Python\Python37\lib\site-packages\asgiref\sync.py", line 223, in __call__
    return call_result.result()
  File "C:\Users\Administrador.WIN-DUOGLHGMSST\AppData\Local\Programs\Python\Python37\lib\concurrent\futures\_base.py", line 428, in result
    return self.__get_result()
  File "C:\Users\Administrador.WIN-DUOGLHGMSST\AppData\Local\Programs\Python\Python37\lib\concurrent\futures\_base.py", line 384, in __get_result
    raise self._exception
  File "C:\Users\Administrador.WIN-DUOGLHGMSST\AppData\Local\Programs\Python\Python37\lib\site-packages\asgiref\sync.py", line 292, in main_wrap
    result = await self.awaitable(*args, **kwargs)
  File "C:\xampp\htdocs\CLANAD_PY\FlaskAPI\app\src\Actividad.py", line 204, in PDF_Actividad
    R1["DATA"] = str(err)
TypeError: '_asyncio.Future' object does not support item assignment
{'TIME':2022-01-05 12:21:56,327,'ADDRESS':'127.0.0.1','URL': 'http://localhost:4000/actividad/PDF?CCODACT=00017192&CTIPSER=R&CCODPLA=72539751002&CNRODNI=99999999&CNRORUC=20125327509&CCODUSU=9999','TYPE':'ERROR','MODULE':'channel','MSG':{Exception while serving /actividad/PDF}}
Traceback (most recent call last):
  File "C:\xampp\htdocs\CLANAD_PY\FlaskAPI\app\src\Actividad.py", line 186, in PDF_Actividad
    raise ValueError("ERROR EN ")
ValueError: ERROR EN 

During handling of the above exception, another exception occurred:

Traceback (most recent call last):
  File "C:\Users\Administrador.WIN-DUOGLHGMSST\AppData\Local\Programs\Python\Python37\lib\site-packages\waitress\channel.py", line 397, in service
    task.service()
  File "C:\Users\Administrador.WIN-DUOGLHGMSST\AppData\Local\Programs\Python\Python37\lib\site-packages\waitress\task.py", line 168, in service
    self.execute()
  File "C:\Users\Administrador.WIN-DUOGLHGMSST\AppData\Local\Programs\Python\Python37\lib\site-packages\waitress\task.py", line 434, in execute
    app_iter = self.channel.server.application(environ, start_response)
  File "C:\Users\Administrador.WIN-DUOGLHGMSST\AppData\Local\Programs\Python\Python37\lib\site-packages\flask\app.py", line 2091, in __call__
    return self.wsgi_app(environ, start_response)
  File "C:\Users\Administrador.WIN-DUOGLHGMSST\AppData\Local\Programs\Python\Python37\lib\site-packages\flask\app.py", line 2076, in wsgi_app
    response = self.handle_exception(e)
  File "C:\Users\Administrador.WIN-DUOGLHGMSST\AppData\Local\Programs\Python\Python37\lib\site-packages\flask\app.py", line 2073, in wsgi_app
    response = self.full_dispatch_request()
  File "C:\Users\Administrador.WIN-DUOGLHGMSST\AppData\Local\Programs\Python\Python37\lib\site-packages\flask\app.py", line 1518, in full_dispatch_request
    rv = self.handle_user_exception(e)
  File "C:\Users\Administrador.WIN-DUOGLHGMSST\AppData\Local\Programs\Python\Python37\lib\site-packages\flask\app.py", line 1516, in full_dispatch_request
    rv = self.dispatch_request()
  File "C:\Users\Administrador.WIN-DUOGLHGMSST\AppData\Local\Programs\Python\Python37\lib\site-packages\flask\app.py", line 1502, in dispatch_request
    return self.ensure_sync(self.view_functions[rule.endpoint])(**req.view_args)
  File "C:\Users\Administrador.WIN-DUOGLHGMSST\AppData\Local\Programs\Python\Python37\lib\site-packages\asgiref\sync.py", line 223, in __call__
    return call_result.result()
  File "C:\Users\Administrador.WIN-DUOGLHGMSST\AppData\Local\Programs\Python\Python37\lib\concurrent\futures\_base.py", line 428, in result
    return self.__get_result()
  File "C:\Users\Administrador.WIN-DUOGLHGMSST\AppData\Local\Programs\Python\Python37\lib\concurrent\futures\_base.py", line 384, in __get_result
    raise self._exception
  File "C:\Users\Administrador.WIN-DUOGLHGMSST\AppData\Local\Programs\Python\Python37\lib\site-packages\asgiref\sync.py", line 292, in main_wrap
    result = await self.awaitable(*args, **kwargs)
  File "C:\xampp\htdocs\CLANAD_PY\FlaskAPI\app\src\Actividad.py", line 205, in PDF_Actividad
    R1["DATA"] = str(err)
TypeError: '_asyncio.Future' object does not support item assignment
{'TIME':2022-01-05 12:24:44,561,'ADDRESS':'127.0.0.1','URL': 'http://localhost:4000/actividad/PDF?CCODACT=00017192&CTIPSER=R&CCODPLA=72539751002&CNRODNI=99999999&CNRORUC=20125327509&CCODUSU=9999','TYPE':'ERROR','MODULE':'channel','MSG':{Exception while serving /actividad/PDF}}
Traceback (most recent call last):
  File "C:\xampp\htdocs\CLANAD_PY\FlaskAPI\app\src\Actividad.py", line 197, in PDF_Actividad
    raise ValueError(err)
ValueError: setHeader() missing 2 required positional arguments: 'codigo' and 'nrohis'

During handling of the above exception, another exception occurred:

Traceback (most recent call last):
  File "C:\Users\Administrador.WIN-DUOGLHGMSST\AppData\Local\Programs\Python\Python37\lib\site-packages\waitress\channel.py", line 397, in service
    task.service()
  File "C:\Users\Administrador.WIN-DUOGLHGMSST\AppData\Local\Programs\Python\Python37\lib\site-packages\waitress\task.py", line 168, in service
    self.execute()
  File "C:\Users\Administrador.WIN-DUOGLHGMSST\AppData\Local\Programs\Python\Python37\lib\site-packages\waitress\task.py", line 434, in execute
    app_iter = self.channel.server.application(environ, start_response)
  File "C:\Users\Administrador.WIN-DUOGLHGMSST\AppData\Local\Programs\Python\Python37\lib\site-packages\flask\app.py", line 2091, in __call__
    return self.wsgi_app(environ, start_response)
  File "C:\Users\Administrador.WIN-DUOGLHGMSST\AppData\Local\Programs\Python\Python37\lib\site-packages\flask\app.py", line 2076, in wsgi_app
    response = self.handle_exception(e)
  File "C:\Users\Administrador.WIN-DUOGLHGMSST\AppData\Local\Programs\Python\Python37\lib\site-packages\flask\app.py", line 2073, in wsgi_app
    response = self.full_dispatch_request()
  File "C:\Users\Administrador.WIN-DUOGLHGMSST\AppData\Local\Programs\Python\Python37\lib\site-packages\flask\app.py", line 1518, in full_dispatch_request
    rv = self.handle_user_exception(e)
  File "C:\Users\Administrador.WIN-DUOGLHGMSST\AppData\Local\Programs\Python\Python37\lib\site-packages\flask\app.py", line 1516, in full_dispatch_request
    rv = self.dispatch_request()
  File "C:\Users\Administrador.WIN-DUOGLHGMSST\AppData\Local\Programs\Python\Python37\lib\site-packages\flask\app.py", line 1502, in dispatch_request
    return self.ensure_sync(self.view_functions[rule.endpoint])(**req.view_args)
  File "C:\Users\Administrador.WIN-DUOGLHGMSST\AppData\Local\Programs\Python\Python37\lib\site-packages\asgiref\sync.py", line 223, in __call__
    return call_result.result()
  File "C:\Users\Administrador.WIN-DUOGLHGMSST\AppData\Local\Programs\Python\Python37\lib\concurrent\futures\_base.py", line 428, in result
    return self.__get_result()
  File "C:\Users\Administrador.WIN-DUOGLHGMSST\AppData\Local\Programs\Python\Python37\lib\concurrent\futures\_base.py", line 384, in __get_result
    raise self._exception
  File "C:\Users\Administrador.WIN-DUOGLHGMSST\AppData\Local\Programs\Python\Python37\lib\site-packages\asgiref\sync.py", line 292, in main_wrap
    result = await self.awaitable(*args, **kwargs)
  File "C:\xampp\htdocs\CLANAD_PY\FlaskAPI\app\src\Actividad.py", line 205, in PDF_Actividad
    R1["DATA"] = str(err)
TypeError: '_asyncio.Future' object does not support item assignment
{'TIME':2022-01-05 12:26:43,716,'ADDRESS':'127.0.0.1','URL': 'http://localhost:4000/actividad/PDF?CCODACT=00017192&CTIPSER=R&CCODPLA=72539751002&CNRODNI=99999999&CNRORUC=20125327509&CCODUSU=9999','TYPE':'ERROR','MODULE':'channel','MSG':{Exception while serving /actividad/PDF}}
Traceback (most recent call last):
  File "C:\xampp\htdocs\CLANAD_PY\FlaskAPI\app\src\Actividad.py", line 197, in PDF_Actividad
    raise ValueError(err)
ValueError: DATOS NO DEFINIDOS

During handling of the above exception, another exception occurred:

Traceback (most recent call last):
  File "C:\Users\Administrador.WIN-DUOGLHGMSST\AppData\Local\Programs\Python\Python37\lib\site-packages\waitress\channel.py", line 397, in service
    task.service()
  File "C:\Users\Administrador.WIN-DUOGLHGMSST\AppData\Local\Programs\Python\Python37\lib\site-packages\waitress\task.py", line 168, in service
    self.execute()
  File "C:\Users\Administrador.WIN-DUOGLHGMSST\AppData\Local\Programs\Python\Python37\lib\site-packages\waitress\task.py", line 434, in execute
    app_iter = self.channel.server.application(environ, start_response)
  File "C:\Users\Administrador.WIN-DUOGLHGMSST\AppData\Local\Programs\Python\Python37\lib\site-packages\flask\app.py", line 2091, in __call__
    return self.wsgi_app(environ, start_response)
  File "C:\Users\Administrador.WIN-DUOGLHGMSST\AppData\Local\Programs\Python\Python37\lib\site-packages\flask\app.py", line 2076, in wsgi_app
    response = self.handle_exception(e)
  File "C:\Users\Administrador.WIN-DUOGLHGMSST\AppData\Local\Programs\Python\Python37\lib\site-packages\flask\app.py", line 2073, in wsgi_app
    response = self.full_dispatch_request()
  File "C:\Users\Administrador.WIN-DUOGLHGMSST\AppData\Local\Programs\Python\Python37\lib\site-packages\flask\app.py", line 1518, in full_dispatch_request
    rv = self.handle_user_exception(e)
  File "C:\Users\Administrador.WIN-DUOGLHGMSST\AppData\Local\Programs\Python\Python37\lib\site-packages\flask\app.py", line 1516, in full_dispatch_request
    rv = self.dispatch_request()
  File "C:\Users\Administrador.WIN-DUOGLHGMSST\AppData\Local\Programs\Python\Python37\lib\site-packages\flask\app.py", line 1502, in dispatch_request
    return self.ensure_sync(self.view_functions[rule.endpoint])(**req.view_args)
  File "C:\Users\Administrador.WIN-DUOGLHGMSST\AppData\Local\Programs\Python\Python37\lib\site-packages\asgiref\sync.py", line 223, in __call__
    return call_result.result()
  File "C:\Users\Administrador.WIN-DUOGLHGMSST\AppData\Local\Programs\Python\Python37\lib\concurrent\futures\_base.py", line 428, in result
    return self.__get_result()
  File "C:\Users\Administrador.WIN-DUOGLHGMSST\AppData\Local\Programs\Python\Python37\lib\concurrent\futures\_base.py", line 384, in __get_result
    raise self._exception
  File "C:\Users\Administrador.WIN-DUOGLHGMSST\AppData\Local\Programs\Python\Python37\lib\site-packages\asgiref\sync.py", line 292, in main_wrap
    result = await self.awaitable(*args, **kwargs)
  File "C:\xampp\htdocs\CLANAD_PY\FlaskAPI\app\src\Actividad.py", line 205, in PDF_Actividad
    R1["DATA"] = str(err)
TypeError: '_asyncio.Future' object does not support item assignment
{'TIME':2022-01-05 12:27:31,302,'ADDRESS':'127.0.0.1','URL': 'http://localhost:4000/actividad/PDF?CCODACT=00017192&CTIPSER=R&CCODPLA=72539751002&CNRODNI=99999999&CNRORUC=20125327509&CCODUSU=9999','TYPE':'ERROR','MODULE':'channel','MSG':{Exception while serving /actividad/PDF}}
Traceback (most recent call last):
  File "C:\xampp\htdocs\CLANAD_PY\FlaskAPI\app\src\Actividad.py", line 197, in PDF_Actividad
    raise ValueError(err)
ValueError: ALGO SALIO MAL AL IMPRIMIR

During handling of the above exception, another exception occurred:

Traceback (most recent call last):
  File "C:\Users\Administrador.WIN-DUOGLHGMSST\AppData\Local\Programs\Python\Python37\lib\site-packages\waitress\channel.py", line 397, in service
    task.service()
  File "C:\Users\Administrador.WIN-DUOGLHGMSST\AppData\Local\Programs\Python\Python37\lib\site-packages\waitress\task.py", line 168, in service
    self.execute()
  File "C:\Users\Administrador.WIN-DUOGLHGMSST\AppData\Local\Programs\Python\Python37\lib\site-packages\waitress\task.py", line 434, in execute
    app_iter = self.channel.server.application(environ, start_response)
  File "C:\Users\Administrador.WIN-DUOGLHGMSST\AppData\Local\Programs\Python\Python37\lib\site-packages\flask\app.py", line 2091, in __call__
    return self.wsgi_app(environ, start_response)
  File "C:\Users\Administrador.WIN-DUOGLHGMSST\AppData\Local\Programs\Python\Python37\lib\site-packages\flask\app.py", line 2076, in wsgi_app
    response = self.handle_exception(e)
  File "C:\Users\Administrador.WIN-DUOGLHGMSST\AppData\Local\Programs\Python\Python37\lib\site-packages\flask\app.py", line 2073, in wsgi_app
    response = self.full_dispatch_request()
  File "C:\Users\Administrador.WIN-DUOGLHGMSST\AppData\Local\Programs\Python\Python37\lib\site-packages\flask\app.py", line 1518, in full_dispatch_request
    rv = self.handle_user_exception(e)
  File "C:\Users\Administrador.WIN-DUOGLHGMSST\AppData\Local\Programs\Python\Python37\lib\site-packages\flask\app.py", line 1516, in full_dispatch_request
    rv = self.dispatch_request()
  File "C:\Users\Administrador.WIN-DUOGLHGMSST\AppData\Local\Programs\Python\Python37\lib\site-packages\flask\app.py", line 1502, in dispatch_request
    return self.ensure_sync(self.view_functions[rule.endpoint])(**req.view_args)
  File "C:\Users\Administrador.WIN-DUOGLHGMSST\AppData\Local\Programs\Python\Python37\lib\site-packages\asgiref\sync.py", line 223, in __call__
    return call_result.result()
  File "C:\Users\Administrador.WIN-DUOGLHGMSST\AppData\Local\Programs\Python\Python37\lib\concurrent\futures\_base.py", line 428, in result
    return self.__get_result()
  File "C:\Users\Administrador.WIN-DUOGLHGMSST\AppData\Local\Programs\Python\Python37\lib\concurrent\futures\_base.py", line 384, in __get_result
    raise self._exception
  File "C:\Users\Administrador.WIN-DUOGLHGMSST\AppData\Local\Programs\Python\Python37\lib\site-packages\asgiref\sync.py", line 292, in main_wrap
    result = await self.awaitable(*args, **kwargs)
  File "C:\xampp\htdocs\CLANAD_PY\FlaskAPI\app\src\Actividad.py", line 205, in PDF_Actividad
    R1["DATA"] = str(err)
TypeError: '_asyncio.Future' object does not support item assignment
{'TIME':2022-01-05 12:28:15,942,'ADDRESS':'127.0.0.1','URL': 'http://localhost:4000/actividad/PDF?CCODACT=00017192&CTIPSER=R&CCODPLA=72539751002&CNRODNI=99999999&CNRORUC=20125327509&CCODUSU=9999','TYPE':'ERROR','MODULE':'channel','MSG':{Exception while serving /actividad/PDF}}
Traceback (most recent call last):
  File "C:\xampp\htdocs\CLANAD_PY\FlaskAPI\app\src\Actividad.py", line 197, in PDF_Actividad
    raise ValueError(err)
ValueError: ALGO SALIO MAL AL IMPRIMIR

During handling of the above exception, another exception occurred:

Traceback (most recent call last):
  File "C:\Users\Administrador.WIN-DUOGLHGMSST\AppData\Local\Programs\Python\Python37\lib\site-packages\waitress\channel.py", line 397, in service
    task.service()
  File "C:\Users\Administrador.WIN-DUOGLHGMSST\AppData\Local\Programs\Python\Python37\lib\site-packages\waitress\task.py", line 168, in service
    self.execute()
  File "C:\Users\Administrador.WIN-DUOGLHGMSST\AppData\Local\Programs\Python\Python37\lib\site-packages\waitress\task.py", line 434, in execute
    app_iter = self.channel.server.application(environ, start_response)
  File "C:\Users\Administrador.WIN-DUOGLHGMSST\AppData\Local\Programs\Python\Python37\lib\site-packages\flask\app.py", line 2091, in __call__
    return self.wsgi_app(environ, start_response)
  File "C:\Users\Administrador.WIN-DUOGLHGMSST\AppData\Local\Programs\Python\Python37\lib\site-packages\flask\app.py", line 2076, in wsgi_app
    response = self.handle_exception(e)
  File "C:\Users\Administrador.WIN-DUOGLHGMSST\AppData\Local\Programs\Python\Python37\lib\site-packages\flask\app.py", line 2073, in wsgi_app
    response = self.full_dispatch_request()
  File "C:\Users\Administrador.WIN-DUOGLHGMSST\AppData\Local\Programs\Python\Python37\lib\site-packages\flask\app.py", line 1518, in full_dispatch_request
    rv = self.handle_user_exception(e)
  File "C:\Users\Administrador.WIN-DUOGLHGMSST\AppData\Local\Programs\Python\Python37\lib\site-packages\flask\app.py", line 1516, in full_dispatch_request
    rv = self.dispatch_request()
  File "C:\Users\Administrador.WIN-DUOGLHGMSST\AppData\Local\Programs\Python\Python37\lib\site-packages\flask\app.py", line 1502, in dispatch_request
    return self.ensure_sync(self.view_functions[rule.endpoint])(**req.view_args)
  File "C:\Users\Administrador.WIN-DUOGLHGMSST\AppData\Local\Programs\Python\Python37\lib\site-packages\asgiref\sync.py", line 223, in __call__
    return call_result.result()
  File "C:\Users\Administrador.WIN-DUOGLHGMSST\AppData\Local\Programs\Python\Python37\lib\concurrent\futures\_base.py", line 428, in result
    return self.__get_result()
  File "C:\Users\Administrador.WIN-DUOGLHGMSST\AppData\Local\Programs\Python\Python37\lib\concurrent\futures\_base.py", line 384, in __get_result
    raise self._exception
  File "C:\Users\Administrador.WIN-DUOGLHGMSST\AppData\Local\Programs\Python\Python37\lib\site-packages\asgiref\sync.py", line 292, in main_wrap
    result = await self.awaitable(*args, **kwargs)
  File "C:\xampp\htdocs\CLANAD_PY\FlaskAPI\app\src\Actividad.py", line 205, in PDF_Actividad
    R1["DATA"] = str(err)
TypeError: '_asyncio.Future' object does not support item assignment
{'TIME':2022-01-05 13:03:04,025,'ADDRESS':'127.0.0.1','URL': 'http://localhost:4000/plan/consentimiento/PDF?CCODACT=00017192&CTIPSER=R&CCODPLA=72539751002&CNRODNI=99999999&CNRORUC=20125327509&CCODUSU=9999','TYPE':'ERROR','MODULE':'channel','MSG':{Exception while serving //plan/consentimiento/PDF}}
Traceback (most recent call last):
  File "C:\xampp\htdocs\CLANAD_PY\FlaskAPI\app\src\PlanActividad.py", line 231, in PDF_Consentimiento
    raise ValueError(err)
ValueError: string indices must be integers

During handling of the above exception, another exception occurred:

Traceback (most recent call last):
  File "C:\Users\Administrador.WIN-DUOGLHGMSST\AppData\Local\Programs\Python\Python37\lib\site-packages\waitress\channel.py", line 397, in service
    task.service()
  File "C:\Users\Administrador.WIN-DUOGLHGMSST\AppData\Local\Programs\Python\Python37\lib\site-packages\waitress\task.py", line 168, in service
    self.execute()
  File "C:\Users\Administrador.WIN-DUOGLHGMSST\AppData\Local\Programs\Python\Python37\lib\site-packages\waitress\task.py", line 434, in execute
    app_iter = self.channel.server.application(environ, start_response)
  File "C:\Users\Administrador.WIN-DUOGLHGMSST\AppData\Local\Programs\Python\Python37\lib\site-packages\flask\app.py", line 2091, in __call__
    return self.wsgi_app(environ, start_response)
  File "C:\Users\Administrador.WIN-DUOGLHGMSST\AppData\Local\Programs\Python\Python37\lib\site-packages\flask\app.py", line 2076, in wsgi_app
    response = self.handle_exception(e)
  File "C:\Users\Administrador.WIN-DUOGLHGMSST\AppData\Local\Programs\Python\Python37\lib\site-packages\flask\app.py", line 2073, in wsgi_app
    response = self.full_dispatch_request()
  File "C:\Users\Administrador.WIN-DUOGLHGMSST\AppData\Local\Programs\Python\Python37\lib\site-packages\flask\app.py", line 1518, in full_dispatch_request
    rv = self.handle_user_exception(e)
  File "C:\Users\Administrador.WIN-DUOGLHGMSST\AppData\Local\Programs\Python\Python37\lib\site-packages\flask\app.py", line 1516, in full_dispatch_request
    rv = self.dispatch_request()
  File "C:\Users\Administrador.WIN-DUOGLHGMSST\AppData\Local\Programs\Python\Python37\lib\site-packages\flask\app.py", line 1502, in dispatch_request
    return self.ensure_sync(self.view_functions[rule.endpoint])(**req.view_args)
  File "C:\Users\Administrador.WIN-DUOGLHGMSST\AppData\Local\Programs\Python\Python37\lib\site-packages\asgiref\sync.py", line 223, in __call__
    return call_result.result()
  File "C:\Users\Administrador.WIN-DUOGLHGMSST\AppData\Local\Programs\Python\Python37\lib\concurrent\futures\_base.py", line 428, in result
    return self.__get_result()
  File "C:\Users\Administrador.WIN-DUOGLHGMSST\AppData\Local\Programs\Python\Python37\lib\concurrent\futures\_base.py", line 384, in __get_result
    raise self._exception
  File "C:\Users\Administrador.WIN-DUOGLHGMSST\AppData\Local\Programs\Python\Python37\lib\site-packages\asgiref\sync.py", line 292, in main_wrap
    result = await self.awaitable(*args, **kwargs)
  File "C:\xampp\htdocs\CLANAD_PY\FlaskAPI\app\src\PlanActividad.py", line 239, in PDF_Consentimiento
    R1["DATA"] = str(err)
TypeError: '_asyncio.Future' object does not support item assignment
{'TIME':2022-01-05 13:04:07,921,'ADDRESS':'127.0.0.1','URL': 'http://localhost:4000/plan/consentimiento/PDF?CCODACT=00017192&CTIPSER=R&CCODPLA=72539751002&CNRODNI=99999999&CNRORUC=20125327509&CCODUSU=9999','TYPE':'ERROR','MODULE':'channel','MSG':{Exception while serving //plan/consentimiento/PDF}}
Traceback (most recent call last):
  File "C:\xampp\htdocs\CLANAD_PY\FlaskAPI\app\src\PlanActividad.py", line 231, in PDF_Consentimiento
    raise ValueError(err)
ValueError: string indices must be integers

During handling of the above exception, another exception occurred:

Traceback (most recent call last):
  File "C:\Users\Administrador.WIN-DUOGLHGMSST\AppData\Local\Programs\Python\Python37\lib\site-packages\waitress\channel.py", line 397, in service
    task.service()
  File "C:\Users\Administrador.WIN-DUOGLHGMSST\AppData\Local\Programs\Python\Python37\lib\site-packages\waitress\task.py", line 168, in service
    self.execute()
  File "C:\Users\Administrador.WIN-DUOGLHGMSST\AppData\Local\Programs\Python\Python37\lib\site-packages\waitress\task.py", line 434, in execute
    app_iter = self.channel.server.application(environ, start_response)
  File "C:\Users\Administrador.WIN-DUOGLHGMSST\AppData\Local\Programs\Python\Python37\lib\site-packages\flask\app.py", line 2091, in __call__
    return self.wsgi_app(environ, start_response)
  File "C:\Users\Administrador.WIN-DUOGLHGMSST\AppData\Local\Programs\Python\Python37\lib\site-packages\flask\app.py", line 2076, in wsgi_app
    response = self.handle_exception(e)
  File "C:\Users\Administrador.WIN-DUOGLHGMSST\AppData\Local\Programs\Python\Python37\lib\site-packages\flask\app.py", line 2073, in wsgi_app
    response = self.full_dispatch_request()
  File "C:\Users\Administrador.WIN-DUOGLHGMSST\AppData\Local\Programs\Python\Python37\lib\site-packages\flask\app.py", line 1518, in full_dispatch_request
    rv = self.handle_user_exception(e)
  File "C:\Users\Administrador.WIN-DUOGLHGMSST\AppData\Local\Programs\Python\Python37\lib\site-packages\flask\app.py", line 1516, in full_dispatch_request
    rv = self.dispatch_request()
  File "C:\Users\Administrador.WIN-DUOGLHGMSST\AppData\Local\Programs\Python\Python37\lib\site-packages\flask\app.py", line 1502, in dispatch_request
    return self.ensure_sync(self.view_functions[rule.endpoint])(**req.view_args)
  File "C:\Users\Administrador.WIN-DUOGLHGMSST\AppData\Local\Programs\Python\Python37\lib\site-packages\asgiref\sync.py", line 223, in __call__
    return call_result.result()
  File "C:\Users\Administrador.WIN-DUOGLHGMSST\AppData\Local\Programs\Python\Python37\lib\concurrent\futures\_base.py", line 428, in result
    return self.__get_result()
  File "C:\Users\Administrador.WIN-DUOGLHGMSST\AppData\Local\Programs\Python\Python37\lib\concurrent\futures\_base.py", line 384, in __get_result
    raise self._exception
  File "C:\Users\Administrador.WIN-DUOGLHGMSST\AppData\Local\Programs\Python\Python37\lib\site-packages\asgiref\sync.py", line 292, in main_wrap
    result = await self.awaitable(*args, **kwargs)
  File "C:\xampp\htdocs\CLANAD_PY\FlaskAPI\app\src\PlanActividad.py", line 239, in PDF_Consentimiento
    R1["DATA"] = str(err)
TypeError: '_asyncio.Future' object does not support item assignment
{'TIME':2022-01-05 13:05:19,786,'ADDRESS':'127.0.0.1','URL': 'http://localhost:4000/plan/consentimiento/PDF?CCODACT=00017192&CTIPSER=R&CCODPLA=72539751002&CNRODNI=99999999&CNRORUC=20125327509&CCODUSU=9999','TYPE':'ERROR','MODULE':'channel','MSG':{Exception while serving //plan/consentimiento/PDF}}
Traceback (most recent call last):
  File "C:\xampp\htdocs\CLANAD_PY\FlaskAPI\app\src\PlanActividad.py", line 231, in PDF_Consentimiento
    raise ValueError(err)
ValueError: string indices must be integers

During handling of the above exception, another exception occurred:

Traceback (most recent call last):
  File "C:\Users\Administrador.WIN-DUOGLHGMSST\AppData\Local\Programs\Python\Python37\lib\site-packages\waitress\channel.py", line 397, in service
    task.service()
  File "C:\Users\Administrador.WIN-DUOGLHGMSST\AppData\Local\Programs\Python\Python37\lib\site-packages\waitress\task.py", line 168, in service
    self.execute()
  File "C:\Users\Administrador.WIN-DUOGLHGMSST\AppData\Local\Programs\Python\Python37\lib\site-packages\waitress\task.py", line 434, in execute
    app_iter = self.channel.server.application(environ, start_response)
  File "C:\Users\Administrador.WIN-DUOGLHGMSST\AppData\Local\Programs\Python\Python37\lib\site-packages\flask\app.py", line 2091, in __call__
    return self.wsgi_app(environ, start_response)
  File "C:\Users\Administrador.WIN-DUOGLHGMSST\AppData\Local\Programs\Python\Python37\lib\site-packages\flask\app.py", line 2076, in wsgi_app
    response = self.handle_exception(e)
  File "C:\Users\Administrador.WIN-DUOGLHGMSST\AppData\Local\Programs\Python\Python37\lib\site-packages\flask\app.py", line 2073, in wsgi_app
    response = self.full_dispatch_request()
  File "C:\Users\Administrador.WIN-DUOGLHGMSST\AppData\Local\Programs\Python\Python37\lib\site-packages\flask\app.py", line 1518, in full_dispatch_request
    rv = self.handle_user_exception(e)
  File "C:\Users\Administrador.WIN-DUOGLHGMSST\AppData\Local\Programs\Python\Python37\lib\site-packages\flask\app.py", line 1516, in full_dispatch_request
    rv = self.dispatch_request()
  File "C:\Users\Administrador.WIN-DUOGLHGMSST\AppData\Local\Programs\Python\Python37\lib\site-packages\flask\app.py", line 1502, in dispatch_request
    return self.ensure_sync(self.view_functions[rule.endpoint])(**req.view_args)
  File "C:\Users\Administrador.WIN-DUOGLHGMSST\AppData\Local\Programs\Python\Python37\lib\site-packages\asgiref\sync.py", line 223, in __call__
    return call_result.result()
  File "C:\Users\Administrador.WIN-DUOGLHGMSST\AppData\Local\Programs\Python\Python37\lib\concurrent\futures\_base.py", line 428, in result
    return self.__get_result()
  File "C:\Users\Administrador.WIN-DUOGLHGMSST\AppData\Local\Programs\Python\Python37\lib\concurrent\futures\_base.py", line 384, in __get_result
    raise self._exception
  File "C:\Users\Administrador.WIN-DUOGLHGMSST\AppData\Local\Programs\Python\Python37\lib\site-packages\asgiref\sync.py", line 292, in main_wrap
    result = await self.awaitable(*args, **kwargs)
  File "C:\xampp\htdocs\CLANAD_PY\FlaskAPI\app\src\PlanActividad.py", line 239, in PDF_Consentimiento
    R1["DATA"] = str(err)
TypeError: '_asyncio.Future' object does not support item assignment
{'TIME':2022-01-05 13:08:00,490,'ADDRESS':'127.0.0.1','URL': 'http://localhost:4000/plan/consentimiento/PDF?CCODACT=00017192&CTIPSER=R&CCODPLA=72539751002&CNRODNI=99999999&CNRORUC=20125327509&CCODUSU=9999','TYPE':'ERROR','MODULE':'channel','MSG':{Exception while serving /plan/consentimiento/PDF}}
Traceback (most recent call last):
  File "C:\xampp\htdocs\CLANAD_PY\FlaskAPI\app\src\PlanActividad.py", line 231, in PDF_Consentimiento
    raise ValueError(err)
ValueError: string indices must be integers

During handling of the above exception, another exception occurred:

Traceback (most recent call last):
  File "C:\Users\Administrador.WIN-DUOGLHGMSST\AppData\Local\Programs\Python\Python37\lib\site-packages\waitress\channel.py", line 397, in service
    task.service()
  File "C:\Users\Administrador.WIN-DUOGLHGMSST\AppData\Local\Programs\Python\Python37\lib\site-packages\waitress\task.py", line 168, in service
    self.execute()
  File "C:\Users\Administrador.WIN-DUOGLHGMSST\AppData\Local\Programs\Python\Python37\lib\site-packages\waitress\task.py", line 434, in execute
    app_iter = self.channel.server.application(environ, start_response)
  File "C:\Users\Administrador.WIN-DUOGLHGMSST\AppData\Local\Programs\Python\Python37\lib\site-packages\flask\app.py", line 2091, in __call__
    return self.wsgi_app(environ, start_response)
  File "C:\Users\Administrador.WIN-DUOGLHGMSST\AppData\Local\Programs\Python\Python37\lib\site-packages\flask\app.py", line 2076, in wsgi_app
    response = self.handle_exception(e)
  File "C:\Users\Administrador.WIN-DUOGLHGMSST\AppData\Local\Programs\Python\Python37\lib\site-packages\flask\app.py", line 2073, in wsgi_app
    response = self.full_dispatch_request()
  File "C:\Users\Administrador.WIN-DUOGLHGMSST\AppData\Local\Programs\Python\Python37\lib\site-packages\flask\app.py", line 1518, in full_dispatch_request
    rv = self.handle_user_exception(e)
  File "C:\Users\Administrador.WIN-DUOGLHGMSST\AppData\Local\Programs\Python\Python37\lib\site-packages\flask\app.py", line 1516, in full_dispatch_request
    rv = self.dispatch_request()
  File "C:\Users\Administrador.WIN-DUOGLHGMSST\AppData\Local\Programs\Python\Python37\lib\site-packages\flask\app.py", line 1502, in dispatch_request
    return self.ensure_sync(self.view_functions[rule.endpoint])(**req.view_args)
  File "C:\Users\Administrador.WIN-DUOGLHGMSST\AppData\Local\Programs\Python\Python37\lib\site-packages\asgiref\sync.py", line 223, in __call__
    return call_result.result()
  File "C:\Users\Administrador.WIN-DUOGLHGMSST\AppData\Local\Programs\Python\Python37\lib\concurrent\futures\_base.py", line 428, in result
    return self.__get_result()
  File "C:\Users\Administrador.WIN-DUOGLHGMSST\AppData\Local\Programs\Python\Python37\lib\concurrent\futures\_base.py", line 384, in __get_result
    raise self._exception
  File "C:\Users\Administrador.WIN-DUOGLHGMSST\AppData\Local\Programs\Python\Python37\lib\site-packages\asgiref\sync.py", line 292, in main_wrap
    result = await self.awaitable(*args, **kwargs)
  File "C:\xampp\htdocs\CLANAD_PY\FlaskAPI\app\src\PlanActividad.py", line 239, in PDF_Consentimiento
    R1["DATA"] = str(err)
TypeError: '_asyncio.Future' object does not support item assignment
{'TIME':2022-01-05 13:08:44,634,'ADDRESS':'127.0.0.1','URL': 'http://localhost:4000/plan/consentimiento/PDF?CCODACT=00017192&CTIPSER=R&CCODPLA=72539751002&CNRODNI=99999999&CNRORUC=20125327509&CCODUSU=9999','TYPE':'ERROR','MODULE':'channel','MSG':{Exception while serving /plan/consentimiento/PDF}}
Traceback (most recent call last):
  File "C:\xampp\htdocs\CLANAD_PY\FlaskAPI\app\src\PlanActividad.py", line 234, in PDF_Consentimiento
    raise ValueError(err)
ValueError: string indices must be integers

During handling of the above exception, another exception occurred:

Traceback (most recent call last):
  File "C:\Users\Administrador.WIN-DUOGLHGMSST\AppData\Local\Programs\Python\Python37\lib\site-packages\waitress\channel.py", line 397, in service
    task.service()
  File "C:\Users\Administrador.WIN-DUOGLHGMSST\AppData\Local\Programs\Python\Python37\lib\site-packages\waitress\task.py", line 168, in service
    self.execute()
  File "C:\Users\Administrador.WIN-DUOGLHGMSST\AppData\Local\Programs\Python\Python37\lib\site-packages\waitress\task.py", line 434, in execute
    app_iter = self.channel.server.application(environ, start_response)
  File "C:\Users\Administrador.WIN-DUOGLHGMSST\AppData\Local\Programs\Python\Python37\lib\site-packages\flask\app.py", line 2091, in __call__
    return self.wsgi_app(environ, start_response)
  File "C:\Users\Administrador.WIN-DUOGLHGMSST\AppData\Local\Programs\Python\Python37\lib\site-packages\flask\app.py", line 2076, in wsgi_app
    response = self.handle_exception(e)
  File "C:\Users\Administrador.WIN-DUOGLHGMSST\AppData\Local\Programs\Python\Python37\lib\site-packages\flask\app.py", line 2073, in wsgi_app
    response = self.full_dispatch_request()
  File "C:\Users\Administrador.WIN-DUOGLHGMSST\AppData\Local\Programs\Python\Python37\lib\site-packages\flask\app.py", line 1518, in full_dispatch_request
    rv = self.handle_user_exception(e)
  File "C:\Users\Administrador.WIN-DUOGLHGMSST\AppData\Local\Programs\Python\Python37\lib\site-packages\flask\app.py", line 1516, in full_dispatch_request
    rv = self.dispatch_request()
  File "C:\Users\Administrador.WIN-DUOGLHGMSST\AppData\Local\Programs\Python\Python37\lib\site-packages\flask\app.py", line 1502, in dispatch_request
    return self.ensure_sync(self.view_functions[rule.endpoint])(**req.view_args)
  File "C:\Users\Administrador.WIN-DUOGLHGMSST\AppData\Local\Programs\Python\Python37\lib\site-packages\asgiref\sync.py", line 223, in __call__
    return call_result.result()
  File "C:\Users\Administrador.WIN-DUOGLHGMSST\AppData\Local\Programs\Python\Python37\lib\concurrent\futures\_base.py", line 428, in result
    return self.__get_result()
  File "C:\Users\Administrador.WIN-DUOGLHGMSST\AppData\Local\Programs\Python\Python37\lib\concurrent\futures\_base.py", line 384, in __get_result
    raise self._exception
  File "C:\Users\Administrador.WIN-DUOGLHGMSST\AppData\Local\Programs\Python\Python37\lib\site-packages\asgiref\sync.py", line 292, in main_wrap
    result = await self.awaitable(*args, **kwargs)
  File "C:\xampp\htdocs\CLANAD_PY\FlaskAPI\app\src\PlanActividad.py", line 242, in PDF_Consentimiento
    R1["DATA"] = str(err)
TypeError: '_asyncio.Future' object does not support item assignment
{'TIME':2022-01-05 13:11:51,684,'ADDRESS':'127.0.0.1','URL': 'http://localhost:4000/plan/consentimiento/PDF?%2FPDF%3FCCODACT=00017192&CTIPSER=R&CCODPLA=72539751002&CNRODNI=99999999&CNRORUC=20125327509&CCODUSU=9999','TYPE':'ERROR','MODULE':'channel','MSG':{Exception while serving /plan/consentimiento/PDF}}
Traceback (most recent call last):
  File "C:\xampp\htdocs\CLANAD_PY\FlaskAPI\app\src\PlanActividad.py", line 232, in PDF_Consentimiento
    R1["OK"] = 1
TypeError: '_asyncio.Future' object does not support item assignment

During handling of the above exception, another exception occurred:

Traceback (most recent call last):
  File "C:\Users\Administrador.WIN-DUOGLHGMSST\AppData\Local\Programs\Python\Python37\lib\site-packages\waitress\channel.py", line 397, in service
    task.service()
  File "C:\Users\Administrador.WIN-DUOGLHGMSST\AppData\Local\Programs\Python\Python37\lib\site-packages\waitress\task.py", line 168, in service
    self.execute()
  File "C:\Users\Administrador.WIN-DUOGLHGMSST\AppData\Local\Programs\Python\Python37\lib\site-packages\waitress\task.py", line 434, in execute
    app_iter = self.channel.server.application(environ, start_response)
  File "C:\Users\Administrador.WIN-DUOGLHGMSST\AppData\Local\Programs\Python\Python37\lib\site-packages\flask\app.py", line 2091, in __call__
    return self.wsgi_app(environ, start_response)
  File "C:\Users\Administrador.WIN-DUOGLHGMSST\AppData\Local\Programs\Python\Python37\lib\site-packages\flask\app.py", line 2076, in wsgi_app
    response = self.handle_exception(e)
  File "C:\Users\Administrador.WIN-DUOGLHGMSST\AppData\Local\Programs\Python\Python37\lib\site-packages\flask\app.py", line 2073, in wsgi_app
    response = self.full_dispatch_request()
  File "C:\Users\Administrador.WIN-DUOGLHGMSST\AppData\Local\Programs\Python\Python37\lib\site-packages\flask\app.py", line 1518, in full_dispatch_request
    rv = self.handle_user_exception(e)
  File "C:\Users\Administrador.WIN-DUOGLHGMSST\AppData\Local\Programs\Python\Python37\lib\site-packages\flask\app.py", line 1516, in full_dispatch_request
    rv = self.dispatch_request()
  File "C:\Users\Administrador.WIN-DUOGLHGMSST\AppData\Local\Programs\Python\Python37\lib\site-packages\flask\app.py", line 1502, in dispatch_request
    return self.ensure_sync(self.view_functions[rule.endpoint])(**req.view_args)
  File "C:\Users\Administrador.WIN-DUOGLHGMSST\AppData\Local\Programs\Python\Python37\lib\site-packages\asgiref\sync.py", line 223, in __call__
    return call_result.result()
  File "C:\Users\Administrador.WIN-DUOGLHGMSST\AppData\Local\Programs\Python\Python37\lib\concurrent\futures\_base.py", line 428, in result
    return self.__get_result()
  File "C:\Users\Administrador.WIN-DUOGLHGMSST\AppData\Local\Programs\Python\Python37\lib\concurrent\futures\_base.py", line 384, in __get_result
    raise self._exception
  File "C:\Users\Administrador.WIN-DUOGLHGMSST\AppData\Local\Programs\Python\Python37\lib\site-packages\asgiref\sync.py", line 292, in main_wrap
    result = await self.awaitable(*args, **kwargs)
  File "C:\xampp\htdocs\CLANAD_PY\FlaskAPI\app\src\PlanActividad.py", line 239, in PDF_Consentimiento
    R1["DATA"] = str(err)
TypeError: '_asyncio.Future' object does not support item assignment
